Workbook

Sheet 운영 정보
D2: 권역 | E2: 코드 | F2: 건물 | H2: 쓰레기 | I2: 재활용 | J2: 음쓰 | M2: 인원 | N2: 코드 | O2: 권역 | P2: 월 | Q2: 화 | R2: 수 | S2: 목 | T2: 금 | U2: 토 | V2: 일 | W2: 빨래 | X2: 건조 | Y2: 이동 | Z2: 비고 | AA2: 연락처 | AB2: 은행 | AC2: 계좌
B3: 침구류 커버, 수건 교체 | D3: 강동 천호 | E3: A | F3: 예건 | H3: 1층 | I3: 1층 | J3: 봉투 | M3: 마디나 | N3: A | O3: 강동 천호 | P3: 월 | Q3: 화 | R3: 수 | T3: 금 | U3: 토 | V3: 일 | W3: ㅇ | Y3: 뚜벅 | Z3: 돈 필요 | AA3: 010-8447-3332 | AB3: 토스 | AC3: 1001-8877-7919
B4: 침구류 머리카락 | F4: 성우 | H4: 1층 | I4: 1층 | J4: 예건 | N4: B | O4: 강동 북천호 | P4: 월 | Q4: 화 | R4: 수 | T4: 금 | U4: 토 | V4: 일 | W4: ㅇ | Y4: 뚜벅 | Z4: 돈 필요
B5: 거울, 유리 | D5: 강동 북천호 | E5: B | F5: 더하임 | H5: 1층 | I5: 1층 | J5: ?? 카드
B6: 스뎅 수전 | F6: 천호다성 | H6: 1층 | I6: 1층 | J6: ?? | M6: 김정은 | N6: A | O6: 강동 천호 | P6: 월 | Q6: 화 | R6: 수 | S6: 목 | T6: 금 | U6: 토 | V6: 일 | W6: ㅇ | X6: ㅇ | Y6: 뚜벅 | AA6: 010-4737-7534 | AB6: 신한 | AC6: 110-611-123497
B7: 채수구 | D7: 강동 중길동 | E7: C | F7: 은성 | H7: 1층 | I7: 1층 | J7: 봉투 | N7: C | O7: 강동 중길동 | P7: 월 | Q7: 화 | R7: 수 | S7: 목 | T7: 금 | U7: 토 | V7: 일 | W7: ㅇ | X7: ㅇ | Y7: 뚜벅
B8: 화장실 물청소, 변기 | F8: 영무 | H8: 1층 | I8: 1층 | J8: 등록 카드 | N8: D | O8: 강동 북길동 | P8: 월 | Q8: 화 | R8: 수 | S8: 목 | T8: 금 | U8: 토 | V8: 일 | W8: ㅇ | X8: ㅇ | Y8: 뚜벅
B9: 선반, 데스크 등 | D9: 강동 북길동 | E9: D | F9: 청광1차 | H9: 1층 | I9: 1층 | N9: E | O9: 강동 남길동 | P9: 월 | Q9: 화 | R9: 수 | S9: 목 | T9: 금 | U9: 토 | V9: 일 | W9: ㅇ | X9: ㅇ | Y9: 뚜벅
B10: 바닥 청소기 | F10: 길동다성 | H10: 1층 | I10: 1층 | N10: F | O10: 강동 남길동 | P10: 월 | Q10: 화 | R10: 수 | S10: 목 | T10: 금 | U10: 토 | V10: 일 | W10: ㅇ | X10: ㅇ | Y10: 뚜벅
B11: 냉장고 비움 | D11: 강동 남길동 | E11: E | F11: 르센티 | H11: 1층 | I11: 1층
B12: 설거지, 렌지 청소 | F12: 동구햇살 | H12: 1층 | I12: 1층
F13: 강동QV | H13: 1층 | I13: 1층 | M13: 유민정 | N13: C | O13: 강동 중길동 | P13: 월 | Q13: 화 | R13: 수 | S13: 목 | T13: 금 | W13: ㅇ | X13: ㅇ | Y13: 뚜벅 | Z13: 2건 이상 | AA13: 010-5906-7472 | AB13: 우체국 | AC13: 013003-02-307591
B14: 빨래 돌리기 | F14: 렘브 | H14: 1층 | I14: 1층 | N14: D | O14: 강동 북길동 | P14: 월 | Q14: 화 | R14: 수 | S14: 목 | T14: 금 | W14: ㅇ | X14: ㅇ | Y14: 뚜벅 | Z14: 2건 이상
D15: 강동 남길동 | E15: F | F15: 청광3차 | H15: 1층 | I15: 1층 | N15: E | O15: 강동 남길동 | P15: 월 | Q15: 화 | R15: 수 | S15: 목 | T15: 금 | W15: ㅇ | X15: ㅇ | Y15: 뚜벅 | Z15: 2건 이상
F16: 한양립스 | H16: 1층 | I16: 1층
F17: sk2차 | M17: 류지영 | O17: 강동 전역 | P17: 월 | Q17: 화 | R17: 수 | S17: 목 | T17: 금 | U17: 토 | V17: 일 | W17: ㅇ | X17: ㅇ | Y17: 자차 | Z17: 남편 | AA17: 010-4509-5717 | AB17: 카카오 | AC17: 3333-1742-08879
D18: 강동 성내 | E18: G | F18: si | H18: 1층 | I18: 1층 | J18: 봉투 | N18: G | O18: 강동 성내 | P18: 월 | Q18: 화 | R18: 수 | S18: 목 | T18: 금 | U18: 토 | V18: 일 | W18: ㅇ | X18: ㅇ | Y18: 자차 | Z18: 남편
F19: 태상 | H19: 1층 | I19: 1층 | J19: 봉투
F20: 오앤 | H20: 1층 | I20: 1층 | M20: 김정한 | O20: 강동 전역 | P20: 월 | Q20: 화 | R20: 수 | S20: 목 | T20: 금 | U20: 토 | V20: 일 | W20: ㅇ | X20: ㅇ | Y20: 자전거 | AA20: 010-7626-1955 | AB20: 신한 | AC20: 110-314-724-430
D21: 송파 오금 | E21: H | F21: 오금스타 | H21: 1층 | I21: 1층 | J21: 봉투
D22: 하남 미사 | E22: I | F22: 미사 마이움 | H22: 지1층 | I22: 지1층 | J22: 지1층 | M22: 박연실 | N22: C | O22: 강동 중길동 | P22: 월 | Q22: 화 | R22: 수 | S22: 목 | T22: 금 | U22: 토 | V22: 일 | W22: ㅇ | X22: ㅇ | Y22: 자전거 | AB22: 기업 | AC22: 060-018435-02-014
F23: 미사 힐스 | H23: 지1층 | I23: 지1층 | J23: 지1층 | N23: D | O23: 강동 북길동 | P23: 월 | Q23: 화 | R23: 수 | S23: 목 | T23: 금 | U23: 토 | V23: 일 | W23: ㅇ | X23: ㅇ | Y23: 자전거
F24: 미사 롯데 | H24: 지1층 | I24: 지1층 | J24: 지1층 | N24: E | O24: 강동 남길동 | P24: 월 | Q24: 화 | R24: 수 | S24: 목 | T24: 금 | U24: 토 | V24: 일 | W24: ㅇ | X24: ㅇ | Y24: 자전거
D25: 중구 | E25: J | F25: 하람휴 | H25: 전봇대 | I25: 전봇대 | J25: 전봇대 | N25: F | O25: 강동 남길동 | P25: 월 | Q25: 화 | R25: 수 | S25: 목 | T25: 금 | U25: 토 | V25: 일 | W25: ㅇ | X25: ㅇ | Y25: 자전거
D26: 동대문 | E26: K | F26: 선일 | H26: 주차장 | I26: 주차장 | J26: 전봇대 | K26: 빨래 수거
F27: 태솔 | H27: 1층 | I27: 1층 | K27: 빨래 수거 | M27: 공숙길 | P27: 월 | Q27: 화 | R27: 수 | S27: 목 | T27: 금 | U27: 토 | V27: 일 | W27: ㅇ | X27: ㅇ | Y27: 뚜벅 | AA27: 010-5520-3206 | AB27: 우체국 | AC27: 013102-02-582835
F28: 뉴시티 | H28: 지2층 | I28: 지2층 | K28: 빨래 수거
D29: 서울 기타 | E29: L | F29: 방학 | H29: 1층 | I29: 1층 | K29: 빨래 수거
F30: 중화 | H30: 1층 | I30: 1층 | J30: 봉투 | K30: 빨래 수거
F31: 가산 | H31: 1층 | I31: 1층 | J31: 등록 카드
D32: 인천 | E32: M | F32: 카이저 | H32: 1층 | I32: 1층 | J32: 교통 카드
D33: 지방 | E33: N | F33: 블루 | M33: 장승연 | N33: C | O33: 강동 중길동 | P33: 월 | Q33: 화 | R33: 수 | S33: 목 | T33: 금 | U33: 토 | V33: 일 | W33: ㅇ | Y33: 뚜벅 | AA33: 010-2773-2244 | AB33: 하나 | AC33: 142-910597-91407
F34: 수아
M35: 강수미 | N35: G | O35: 강동 성내 | P35: 월 | T35: 금 | U35: 토 | V35: 일 | W35: ㅇ | X35: ㅇ | Y35: 뚜벅 | AA35: 010-2272-4424 | AB35: 신한 | AC35: 110-191-641767
N36: H | O36: 송파 오금 | P36: 월 | T36: 금 | V36: 일 | W36: ㅇ | X36: ㅇ | Y36: 뚜벅 | Z36: 빨래 수거
M38: 박진성 | N38: H | O38: 송파 오금 | Q38: 화 | R38: 수 | S38: 목 | U38: 토 | Y38: 뚜벅 | AA38: 010-6288-7469 | AB38: 농협 | AC38: 100029-56-096965
M40: 김민주 | N40: I | O40: 하남 미사 | P40: 월 | Q40: 화 | R40: 수 | S40: 목 | T40: 금 | U40: 토 | V40: 일 | W40: ㅇ | X40: ㅇ | AB40: 기업 | AC40: 540-004738-02-011
M42: 김영숙 | N42: K | O42: 동대문 | P42: 월 | Q42: 화 | R42: 수 | S42: 목 | T42: 금 | U42: 토 | V42: 일 | W42: ㅇ | X42: ㅇ | Y42: 뚜벅 | AA42: 010-3319-8759 | AB42: 국민 | AC42: 450902-01-350165
M43: 안현기 | N43: K | O43: 동대문, 중화 | P43: 월 | Q43: 화 | R43: 수 | S43: 목 | T43: 금 | U43: 토 | V43: 일 | W43: ㅇ | Y43: 뚜벅 | AA43: 010-6261-2659 | AB43: 카카오 | AC43: 3333-0808-48445
M44: 장미숙 | N44: K | O44: 방학, 동대문, 중화 | P44: 월 | Q44: 화 | R44: 수 | S44: 목 | T44: 금 | U44: 토 | V44: 일 | W44: ㅇ | X44: ㅇ | AA44: 010-3767-3054 | AB44: 국민 | AC44: 83470204316717
...

Sheet 청소코드
C2: 1 | D2: 2 | E2: 3 | F2: 4 | G2: 5 | H2: 6 | I2: 7 | J2: 8
B3: 번 | C3: 코드 | D3: 권역 | E3: 명칭 | F3: 방 | G3: Q | H3: ss | I3: 화 | J3: 단가 | L3: 방 개수 | M3: 단가 | T3: 단가 기준
B4: 1 | C4: A22 | D4: A 강동 천호 | E4: 예건 202 | F4: 1 | G4: 1 | I4: 1 | J4: =VLOOKUP(F4,$L$3:$M$8,2,0) -> 18000 | L4: 1 | M4: 18000
B5: 2 | C5: A24 | D5: A 강동 천호 | E5: 예건 204 | F5: 1 | G5: 1 | I5: 1 | J5: =VLOOKUP(F5,$L$3:$M$8,2,0) -> 18000 | L5: 1.5 | M5: 20000 | T5: 방 | U5: 11000 | V5: 14000 | W5: 17000 | X5: 20000
B6: 3 | C6: A25 | D6: A 강동 천호 | E6: 예건 205 | F6: 1 | G6: 1 | I6: 1 | J6: =VLOOKUP(F6,$L$3:$M$8,2,0) -> 18000 | L6: 복 | M6: 20000 | T6: 침대 | U6: 2000
B7: 4 | C7: A33 | D7: A 강동 천호 | E7: 예건 303 | F7: 2 | H7: 3 | I7: 1 | J7: =VLOOKUP(F7,$L$3:$M$8,2,0) -> 23000 | L7: 2 | M7: 23000 | T7: 화장실 | U7: 2000
B8: 5 | C8: A44 | D8: A 강동 천호 | E8: 예건 404 | F8: 1 | G8: 1 | I8: 1 | J8: =VLOOKUP(F8,$L$3:$M$8,2,0) -> 18000 | L8: 3 | M8: 30000
B9: 6 | C9: A62 | D9: A 강동 천호 | E9: 예건 602 | F9: 1 | G9: 1 | I9: 1 | J9: =VLOOKUP(F9,$L$3:$M$8,2,0) -> 18000 | L9: 인천 M1 | M9: 50000 | U9: 방 | Y9: 침대 | AC9: 화장실 | AE9: 단가
B10: 7 | C10: A72 | D10: A 강동 천호 | E10: 예건 702 | F10: 1 | G10: 1 | I10: 1 | J10: =VLOOKUP(F10,$L$3:$M$8,2,0) -> 18000 | L10: 인천 M2 | M10: 30000 | U10: 1 | V10: 1.5 | W10: 2 | X10: 3 | Y10: 1 | Z10: 2 | AA10: 3 | AB10: 4 | AC10: 1 | AD10: 2
B11: 8 | C11: A82 | D11: A 강동 천호 | E11: 예건 802 | F11: 1 | G11: 1 | I11: 1 | J11: =VLOOKUP(F11,$L$3:$M$8,2,0) -> 18000 | U11: =U5 -> 11000 | V11: =V5 -> 14000 | W11: =W5 -> 17000 | X11: =X5 -> 20000 | Y11: =$U$6*Y10 -> 2000 | Z11: =$U$6*Z10 -> 4000 | AA11: =$U$6*AA10 -> 6000 | AB11: =$U$6*AB10 -> 8000 | AC11: =$U$7*AC10 -> 2000 | AD11: =$U$7*AD10 -> 4000
B12: 9 | C12: A92 | D12: A 강동 천호 | E12: 예건 902 | F12: 1 | G12: 1 | I12: 1 | J12: =VLOOKUP(F12,$L$3:$M$8,2,0) -> 18000 | T12: 1룸 1베드 | U12: =$U$11 -> 11000 | Y12: =$Y$11 -> 2000 | AC12: =$AC$11 -> 2000 | AE12: =SUM(U12:AD12) -> 15000
B13: 10 | C13: B101 | D13: A2 강동 북천호 | E13: 더하임 1001 | F13: 1 | J13: =VLOOKUP(F13,$L$3:$M$8,2,0) -> 18000 | T13: 1룸 2베드 | U13: =$U$11 -> 11000 | Z13: =$Z$11 -> 4000 | AC13: =$AC$11 -> 2000 | AE13: =SUM(U13:AD13) -> 17000
B14: 11 | C14: B102 | D14: A2 강동 북천호 | E14: 더하임 1002 | F14: 1 | J14: =VLOOKUP(F14,$L$3:$M$8,2,0) -> 18000 | T14: 1룸 3베드 | U14: =$U$11 -> 11000 | AA14: =$AA$11 -> 6000 | AC14: =$AC$11 -> 2000 | AE14: =SUM(U14:AD14) -> 19000
B15: 12 | C15: B103 | D15: A2 강동 북천호 | E15: 더하임 1003 | F15: 1 | J15: =VLOOKUP(F15,$L$3:$M$8,2,0) -> 18000 | T15: 복층 1베드 | V15: =$V$11 -> 14000 | Y15: =$Y$11 -> 2000 | AC15: =$AC$11 -> 2000 | AE15: =SUM(U15:AD15) -> 18000
B16: 13 | C16: B104 | D16: A2 강동 북천호 | E16: 더하임 1004 | F16: 1 | J16: =VLOOKUP(F16,$L$3:$M$8,2,0) -> 18000 | T16: 복층 2베드 | V16: =$V$11 -> 14000 | Z16: =$Z$11 -> 4000 | AC16: =$AC$11 -> 2000 | AE16: =SUM(U16:AD16) -> 20000
B17: 14 | C17: B105 | D17: A2 강동 북천호 | E17: 더하임 1005 | F17: 1 | J17: =VLOOKUP(F17,$L$3:$M$8,2,0) -> 18000 | T17: 복층 3베드 | V17: =$V$11 -> 14000 | AA17: =$AA$11 -> 6000 | AC17: =$AC$11 -> 2000 | AE17: =SUM(U17:AD17) -> 22000
B18: 15 | C18: B106 | D18: A2 강동 북천호 | E18: 더하임 1006 | F18: 1.5 | J18: =VLOOKUP(F18,$L$3:$M$8,2,0) -> 20000 | T18: 1.5룸 1베드 | V18: =$V$11 -> 14000 | Y18: =$Y$11 -> 2000 | AC18: =$AC$11 -> 2000 | AE18: =SUM(U18:AD18) -> 18000
B19: 16 | C19: B22 | D19: A2 강동 북천호 | E19: 더하임 202 | F19: 1 | J19: =VLOOKUP(F19,$L$3:$M$8,2,0) -> 18000 | T19: 1.5룸 2베드 | V19: =$V$11 -> 14000 | Z19: =$Z$11 -> 4000 | AC19: =$AC$11 -> 2000 | AE19: =SUM(U19:AD19) -> 20000
B20: 17 | C20: B23 | D20: A2 강동 북천호 | E20: 더하임 203 | F20: 1 | J20: =VLOOKUP(F20,$L$3:$M$8,2,0) -> 18000 | T20: 2룸 2베드 | W20: =$W$11 -> 17000 | Z20: =$Z$11 -> 4000 | AC20: =$AC$11 -> 2000 | AE20: =SUM(U20:AD20) -> 23000
B21: 18 | C21: B24 | D21: A2 강동 북천호 | E21: 더하임 204 | F21: 1 | G21: 1 | I21: 1 | J21: =VLOOKUP(F21,$L$3:$M$8,2,0) -> 18000 | T21: 2룸 3베드 | W21: =$W$11 -> 17000 | AA21: =$AA$11 -> 6000 | AC21: =$AC$11 -> 2000 | AE21: =SUM(U21:AD21) -> 25000
B22: 19 | C22: B25 | D22: A2 강동 북천호 | E22: 더하임 205 | F22: 1 | J22: =VLOOKUP(F22,$L$3:$M$8,2,0) -> 18000 | T22: 2룸 2베드 2화 | W22: =$W$11 -> 17000 | Z22: =$Z$11 -> 4000 | AD22: =$AD$11 -> 4000 | AE22: =SUM(U22:AD22) -> 25000
B23: 20 | C23: B34 | D23: A2 강동 북천호 | E23: 더하임 304 | F23: 1 | G23: 1 | I23: 1 | J23: =VLOOKUP(F23,$L$3:$M$8,2,0) -> 18000 | T23: 2룸 3베드 2화 | W23: =$W$11 -> 17000 | AA23: =$AA$11 -> 6000 | AD23: =$AD$11 -> 4000 | AE23: =SUM(U23:AD23) -> 27000
B24: 21 | C24: B35 | D24: A2 강동 북천호 | E24: 더하임 305 | F24: 1 | G24: 1 | I24: 1 | J24: =VLOOKUP(F24,$L$3:$M$8,2,0) -> 18000 | T24: 3룸 3베드 | X24: =$X$11 -> 20000 | AA24: =$AA$11 -> 6000 | AC24: =$AC$11 -> 2000 | AE24: =SUM(U24:AD24) -> 28000
B25: 22 | C25: B36 | D25: A2 강동 북천호 | E25: 더하임 306 | F25: 1.5 | G25: 2 | I25: 1 | J25: =VLOOKUP(F25,$L$3:$M$8,2,0) -> 20000 | T25: 3룸 3베드 2화 | X25: =$X$11 -> 20000 | AA25: =$AA$11 -> 6000 | AD25: =$AD$11 -> 4000 | AE25: =SUM(U25:AD25) -> 30000
B26: 23 | C26: B46 | D26: A2 강동 북천호 | E26: 더하임 406 | F26: 1.5 | G26: 1 | I26: 1 | J26: =VLOOKUP(F26,$L$3:$M$8,2,0) -> 20000 | T26: 3룸 4베드 | X26: =$X$11 -> 20000 | AB26: =$AB$11 -> 8000 | AC26: =$AC$11 -> 2000 | AE26: =SUM(U26:AD26) -> 30000
B27: 24 | C27: B54 | D27: A2 강동 북천호 | E27: 더하임 504 | F27: 1 | G27: 1 | I27: 1 | J27: =VLOOKUP(F27,$L$3:$M$8,2,0) -> 18000
B28: 25 | C28: B55 | D28: A2 강동 북천호 | E28: 더하임 505 | F28: 1 | G28: 1 | I28: 1 | J28: =VLOOKUP(F28,$L$3:$M$8,2,0) -> 18000
B29: 26 | C29: B56 | D29: A2 강동 북천호 | E29: 더하임 506 | F29: 1.5 | G29: 2 | I29: 1 | J29: =VLOOKUP(F29,$L$3:$M$8,2,0) -> 20000
B30: 27 | C30: B64 | D30: A2 강동 북천호 | E30: 더하임 604 | F30: 1 | G30: 1 | I30: 1 | J30: =VLOOKUP(F30,$L$3:$M$8,2,0) -> 18000
B31: 28 | C31: B76 | D31: A2 강동 북천호 | E31: 더하임 706 | F31: 1.5 | G31: 1 | I31: 1 | J31: =VLOOKUP(F31,$L$3:$M$8,2,0) -> 20000
B32: 29 | C32: B91 | D32: A2 강동 북천호 | E32: 더하임 901 | F32: 1 | J32: =VLOOKUP(F32,$L$3:$M$8,2,0) -> 18000
B33: 30 | C33: B93 | D33: A2 강동 북천호 | E33: 더하임 903 | F33: 1 | J33: =VLOOKUP(F33,$L$3:$M$8,2,0) -> 18000
B34: 31 | C34: B94 | D34: A2 강동 북천호 | E34: 더하임 904 | F34: 1 | J34: =VLOOKUP(F34,$L$3:$M$8,2,0) -> 18000 | U34: 방
B35: 32 | C35: B95 | D35: A2 강동 북천호 | E35: 더하임 905 | F35: 1 | J35: =VLOOKUP(F35,$L$3:$M$8,2,0) -> 18000 | U35: 1 | V35: 1.5 / 복 | W35: 2 | X35: 3
B36: 33 | C36: C | D36: C 강동 북길동 | E36: 청광1차 207 | J36: 10000 | U36: 11000 | V36: 14000 | W36: 17000 | X36: 20000
B37: 34 | C37: C2 | D37: C 강동 북길동 | E37: 청광1차 608 | F37: 1 | H37: 2 | I37: 1 | J37: =VLOOKUP(F37,$L$3:$M$8,2,0) -> 18000 | U37: 침대
B38: 35 | C38: C3 | D38: C 강동 북길동 | E38: 청광1차 609 | F38: 1 | G38: 1 | I38: 1 | J38: =VLOOKUP(F38,$L$3:$M$8,2,0) -> 18000 | U38: 1 | V38: 2 | W38: 3 | X38: 4
B39: 36 | C39: C4 | D39: C 강동 북길동 | E39: 청광1차 709 | F39: 1 | G39: 1 | I39: 1 | J39: =VLOOKUP(F39,$L$3:$M$8,2,0) -> 18000 | U39: 2000 | V39: 4000 | W39: 6000 | X39: 8000
B40: 37 | C40: C5 | D40: C 강동 북길동 | E40: 청광1차 910 | F40: 1 | G40: 1 | I40: 1 | J40: =VLOOKUP(F40,$L$3:$M$8,2,0) -> 18000 | U40: 화장실
B41: 38 | C41: C6 | D41: C 강동 북길동 | E41: 청광1차 1303 | F41: 1 | G41: 1 | I41: 1 | J41: =VLOOKUP(F41,$L$3:$M$8,2,0) -> 18000 | U41: 1 | V41: 2
...

Sheet 과거
A1: 청소일자 | B1: 요일 | C1: 코드 | D1: 숙소명 | E1: 방 | F1: 워크맨 | G1: 체크사항/요구사항 | H1: 입금체크 | I1: 입력체크 | J1: 운영 지출
A2: 청소일자 | B2: 요일 | C2: 코드 | D2: 숙소명 | E2: 수 | F2: 담당 | G2: 체크사항/요구사항 | H2: 입금체크 | I2: 입력체크 | J2: 총 금액(B) | K2: 기본비 | L2: 추가비 | M2: 침구 관리 | N2: 물품 구입 | O2: 백업
A3: 46055 | B3: =TEXT(A3,"aaa") -> 월 | C3: T46 | D3: =VLOOKUP($C3,청소코드!$C$4:$J$188,3,FALSE) -> 센텀 2차 406 | E3: =VLOOKUP($C3,청소코드!$C$4:$J$188,4,FALSE) -> 1.5 | F3: 공숙길 | G3: 기상악화 | I3: 완료 | J3: =SUM(K3:O3) -> 25000 | K3: =VLOOKUP($C3,청소코드!$C$4:$J$188,8,FALSE) -> 20000 | L3: 5000
A4: 46055 | B4: =TEXT(A4,"aaa") -> 월 | C4: U83 | D4: =VLOOKUP($C4,청소코드!$C$4:$J$188,3,FALSE) -> 성우 803 | E4: =VLOOKUP($C4,청소코드!$C$4:$J$188,4,FALSE) -> 3 | F4: 김정은 | G4: 기상악화, 세면대 고장 | I4: 완료 | J4: =SUM(K4:O4) -> 35000 | K4: =VLOOKUP($C4,청소코드!$C$4:$J$188,8,FALSE) -> 30000 | L4: 5000
A5: 46055 | B5: =TEXT(A5,"aaa") -> 월 | C5: A62 | D5: =VLOOKUP($C5,청소코드!$C$4:$J$188,3,FALSE) -> 예건 602 | E5: =VLOOKUP($C5,청소코드!$C$4:$J$188,4,FALSE) -> 1 | F5: 김정은 | I5: 완료 | J5: =SUM(K5:O5) -> 18000 | K5: =VLOOKUP($C5,청소코드!$C$4:$J$188,8,FALSE) -> 18000
A6: 46055 | B6: =TEXT(A6,"aaa") -> 월 | C6: B36 | D6: =VLOOKUP($C6,청소코드!$C$4:$J$188,3,FALSE) -> 더하임 306 | E6: =VLOOKUP($C6,청소코드!$C$4:$J$188,4,FALSE) -> 1.5 | F6: 류지영 | G6: 기상악화 | I6: 완료 | J6: =SUM(K6:O6) -> 25000 | K6: =VLOOKUP($C6,청소코드!$C$4:$J$188,8,FALSE) -> 20000 | L6: 5000
A7: 46055 | B7: =TEXT(A7,"aaa") -> 월 | C7: B54 | D7: =VLOOKUP($C7,청소코드!$C$4:$J$188,3,FALSE) -> 더하임 504 | E7: =VLOOKUP($C7,청소코드!$C$4:$J$188,4,FALSE) -> 1 | F7: 류지영 | I7: 완료 | J7: =SUM(K7:O7) -> 18000 | K7: =VLOOKUP($C7,청소코드!$C$4:$J$188,8,FALSE) -> 18000
A8: 46055 | B8: =TEXT(A8,"aaa") -> 월 | C8: B56 | D8: =VLOOKUP($C8,청소코드!$C$4:$J$188,3,FALSE) -> 더하임 506 | E8: =VLOOKUP($C8,청소코드!$C$4:$J$188,4,FALSE) -> 1.5 | F8: 류지영 | I8: 완료 | J8: =SUM(K8:O8) -> 20000 | K8: =VLOOKUP($C8,청소코드!$C$4:$J$188,8,FALSE) -> 20000
A9: 46055 | B9: =TEXT(A9,"aaa") -> 월 | C9: B64 | D9: =VLOOKUP($C9,청소코드!$C$4:$J$188,3,FALSE) -> 더하임 604 | E9: =VLOOKUP($C9,청소코드!$C$4:$J$188,4,FALSE) -> 1 | F9: 류지영 | I9: 완료 | J9: =SUM(K9:O9) -> 18000 | K9: =VLOOKUP($C9,청소코드!$C$4:$J$188,8,FALSE) -> 18000
A10: 46055 | B10: =TEXT(A10,"aaa") -> 월 | C10: D1 | D10: =VLOOKUP($C10,청소코드!$C$4:$J$188,3,FALSE) -> 청광3차 1416 | E10: =VLOOKUP($C10,청소코드!$C$4:$J$188,4,FALSE) -> 1 | F10: 마디나 | G10: 기상악화 | I10: 완료 | J10: =SUM(K10:O10) -> 23000 | K10: =VLOOKUP($C10,청소코드!$C$4:$J$188,8,FALSE) -> 18000 | L10: 5000
A11: 46055 | B11: =TEXT(A11,"aaa") -> 월 | C11: D6 | D11: =VLOOKUP($C11,청소코드!$C$4:$J$188,3,FALSE) -> 청광3차 1412 | E11: =VLOOKUP($C11,청소코드!$C$4:$J$188,4,FALSE) -> 1 | F11: 마디나 | I11: 완료 | J11: =SUM(K11:O11) -> 18000 | K11: =VLOOKUP($C11,청소코드!$C$4:$J$188,8,FALSE) -> 18000
A12: 46055 | B12: =TEXT(A12,"aaa") -> 월 | C12: E1 | D12: =VLOOKUP($C12,청소코드!$C$4:$J$188,3,FALSE) -> 르센티 1801 | E12: =VLOOKUP($C12,청소코드!$C$4:$J$188,4,FALSE) -> 복 | F12: 박연실 | G12: 기상악화 | I12: 완료 | J12: =SUM(K12:O12) -> 25000 | K12: =VLOOKUP($C12,청소코드!$C$4:$J$188,8,FALSE) -> 20000 | L12: 5000
A13: 46055 | B13: =TEXT(A13,"aaa") -> 월 | C13: F2 | D13: =VLOOKUP($C13,청소코드!$C$4:$J$188,3,FALSE) -> 오앤 401 | E13: =VLOOKUP($C13,청소코드!$C$4:$J$188,4,FALSE) -> 1 | F13: 박연실 | I13: 완료 | J13: =SUM(K13:O13) -> 18000 | K13: =VLOOKUP($C13,청소코드!$C$4:$J$188,8,FALSE) -> 18000
A14: 46055 | B14: =TEXT(A14,"aaa") -> 월 | C14: C | D14: =VLOOKUP($C14,청소코드!$C$4:$J$188,3,FALSE) -> 청광1차 207 | E14: =VLOOKUP($C14,청소코드!$C$4:$J$188,4,FALSE) -> 0 | F14: 박연실 | I14: 완료 | J14: =SUM(K14:O14) -> 10000 | K14: =VLOOKUP($C14,청소코드!$C$4:$J$188,8,FALSE) -> 10000
A15: 46056 | B15: =TEXT(A15,"aaa") -> 화 | C15: T51 | D15: =VLOOKUP($C15,청소코드!$C$4:$J$188,3,FALSE) -> 센텀 2차 501 | E15: =VLOOKUP($C15,청소코드!$C$4:$J$188,4,FALSE) -> 1.5 | F15: 김정은 | I15: 완료 | J15: =SUM(K15:O15) -> 20000 | K15: =VLOOKUP($C15,청소코드!$C$4:$J$188,8,FALSE) -> 20000
A16: 46056 | B16: =TEXT(A16,"aaa") -> 화 | C16: A62 | D16: =VLOOKUP($C16,청소코드!$C$4:$J$188,3,FALSE) -> 예건 602 | E16: =VLOOKUP($C16,청소코드!$C$4:$J$188,4,FALSE) -> 1 | F16: 김정은 | G16: 침대 수리필요 | I16: 완료 | J16: =SUM(K16:O16) -> 18000 | K16: =VLOOKUP($C16,청소코드!$C$4:$J$188,8,FALSE) -> 18000
A17: 46056 | B17: =TEXT(A17,"aaa") -> 화 | C17: B24 | D17: =VLOOKUP($C17,청소코드!$C$4:$J$188,3,FALSE) -> 더하임 204 | E17: =VLOOKUP($C17,청소코드!$C$4:$J$188,4,FALSE) -> 1 | F17: 류지영 | I17: 완료 | J17: =SUM(K17:O17) -> 18000 | K17: =VLOOKUP($C17,청소코드!$C$4:$J$188,8,FALSE) -> 18000
A18: 46056 | B18: =TEXT(A18,"aaa") -> 화 | C18: B54 | D18: =VLOOKUP($C18,청소코드!$C$4:$J$188,3,FALSE) -> 더하임 504 | E18: =VLOOKUP($C18,청소코드!$C$4:$J$188,4,FALSE) -> 1 | F18: 류지영 | I18: 완료 | J18: =SUM(K18:O18) -> 18000 | K18: =VLOOKUP($C18,청소코드!$C$4:$J$188,8,FALSE) -> 18000
A19: 46056 | B19: =TEXT(A19,"aaa") -> 화 | C19: B64 | D19: =VLOOKUP($C19,청소코드!$C$4:$J$188,3,FALSE) -> 더하임 604 | E19: =VLOOKUP($C19,청소코드!$C$4:$J$188,4,FALSE) -> 1 | F19: 류지영 | I19: 완료 | J19: =SUM(K19:O19) -> 18000 | K19: =VLOOKUP($C19,청소코드!$C$4:$J$188,8,FALSE) -> 18000
A20: 46056 | B20: =TEXT(A20,"aaa") -> 화 | C20: D3 | D20: =VLOOKUP($C20,청소코드!$C$4:$J$188,3,FALSE) -> 청광3차 507 | E20: =VLOOKUP($C20,청소코드!$C$4:$J$188,4,FALSE) -> 1 | F20: 유민정 | I20: 완료 | J20: =SUM(K20:O20) -> 18000 | K20: =VLOOKUP($C20,청소코드!$C$4:$J$188,8,FALSE) -> 18000
A21: 46056 | B21: =TEXT(A21,"aaa") -> 화 | C21: D6 | D21: =VLOOKUP($C21,청소코드!$C$4:$J$188,3,FALSE) -> 청광3차 1412 | E21: =VLOOKUP($C21,청소코드!$C$4:$J$188,4,FALSE) -> 1 | F21: 유민정 | I21: 완료 | J21: =SUM(K21:O21) -> 18000 | K21: =VLOOKUP($C21,청소코드!$C$4:$J$188,8,FALSE) -> 18000
A22: 46056 | B22: =TEXT(A22,"aaa") -> 화 | C22: D8 | D22: =VLOOKUP($C22,청소코드!$C$4:$J$188,3,FALSE) -> 강동QV 1604 | E22: =VLOOKUP($C22,청소코드!$C$4:$J$188,4,FALSE) -> 1 | F22: 공숙길 | I22: 완료 | J22: =SUM(K22:O22) -> 18000 | K22: =VLOOKUP($C22,청소코드!$C$4:$J$188,8,FALSE) -> 18000
A23: 46056 | B23: =TEXT(A23,"aaa") -> 화 | C23: E1 | D23: =VLOOKUP($C23,청소코드!$C$4:$J$188,3,FALSE) -> 르센티 1801 | E23: =VLOOKUP($C23,청소코드!$C$4:$J$188,4,FALSE) -> 복 | F23: 공숙길 | I23: 완료 | J23: =SUM(K23:O23) -> 20000 | K23: =VLOOKUP($C23,청소코드!$C$4:$J$188,8,FALSE) -> 20000
A24: 46056 | B24: =TEXT(A24,"aaa") -> 화 | C24: F2 | D24: =VLOOKUP($C24,청소코드!$C$4:$J$188,3,FALSE) -> 오앤 401 | E24: =VLOOKUP($C24,청소코드!$C$4:$J$188,4,FALSE) -> 1 | F24: 박연실 | I24: 완료 | J24: =SUM(K24:O24) -> 18000 | K24: =VLOOKUP($C24,청소코드!$C$4:$J$188,8,FALSE) -> 18000
A25: 46056 | B25: =TEXT(A25,"aaa") -> 화 | C25: C | D25: =VLOOKUP($C25,청소코드!$C$4:$J$188,3,FALSE) -> 청광1차 207 | E25: =VLOOKUP($C25,청소코드!$C$4:$J$188,4,FALSE) -> 0 | F25: 박연실 | I25: 완료 | J25: =SUM(K25:O25) -> 10000 | K25: =VLOOKUP($C25,청소코드!$C$4:$J$188,8,FALSE) -> 10000
A26: 46057 | B26: =TEXT(A26,"aaa") -> 수 | C26: V13 | D26: =VLOOKUP($C26,청소코드!$C$4:$J$188,3,FALSE) -> 대치동 103호 | E26: =VLOOKUP($C26,청소코드!$C$4:$J$188,4,FALSE) -> 1.5 | F26: 오재관 | I26: 완료 | J26: =SUM(K26:O26) -> 20000 | K26: =VLOOKUP($C26,청소코드!$C$4:$J$188,8,FALSE) -> 20000
A27: 46057 | B27: =TEXT(A27,"aaa") -> 수 | C27: T46 | D27: =VLOOKUP($C27,청소코드!$C$4:$J$188,3,FALSE) -> 센텀 2차 406 | E27: =VLOOKUP($C27,청소코드!$C$4:$J$188,4,FALSE) -> 1.5 | F27: 마디나 | I27: 완료 | J27: =SUM(K27:O27) -> 20000 | K27: =VLOOKUP($C27,청소코드!$C$4:$J$188,8,FALSE) -> 20000
A28: 46057 | B28: =TEXT(A28,"aaa") -> 수 | C28: T51 | D28: =VLOOKUP($C28,청소코드!$C$4:$J$188,3,FALSE) -> 센텀 2차 501 | E28: =VLOOKUP($C28,청소코드!$C$4:$J$188,4,FALSE) -> 1.5 | F28: 마디나 | I28: 완료 | J28: =SUM(K28:O28) -> 20000 | K28: =VLOOKUP($C28,청소코드!$C$4:$J$188,8,FALSE) -> 20000
... A43: 46058 | B43: =TEXT(A43,"aaa") -> 목 | C43: E1 | D43: =VLOOKUP($C43,청소코드!$C$4:$J$188,3,FALSE) -> 르센티 1801 | E43: =VLOOKUP($C43,청소코드!$C$4:$J$188,4,FALSE) -> 복 | F43: 유민정 | I43: 완료 | J43: =SUM(K43:O43) -> 20000 | K43: =VLOOKUP($C43,청소코드!$C$4:$J$188,8,FALSE) -> 20000
A44: 46058 | B44: =TEXT(A44,"aaa") -> 목 | C44: E5 | D44: =VLOOKUP($C44,청소코드!$C$4:$J$188,3,FALSE) -> 동구햇살 1203 | E44: =VLOOKUP($C44,청소코드!$C$4:$J$188,4,FALSE) -> 복 | F44: 김정은 | G44: 종랑제처리, 귤값 | I44: 완료 | J44: =SUM(K44:O44) -> 30000 | K44: =VLOOKUP($C44,청소코드!$C$4:$J$188,8,FALSE) -> 20000 | L44: 10000
A45: 46058 | B45: =TEXT(A45,"aaa") -> 목 | C45: A72 | D45: =VLOOKUP($C45,청소코드!$C$4:$J$188,3,FALSE) -> 예건 702 | E45: =VLOOKUP($C45,청소코드!$C$4:$J$188,4,FALSE) -> 1 | F45: 김정은 | I45: 완료 | J45: =SUM(K45:O45) -> 18000 | K45: =VLOOKUP($C45,청소코드!$C$4:$J$188,8,FALSE) -> 18000
A46: 46058 | B46: =TEXT(A46,"aaa") -> 목 | C46: T46 | D46: =VLOOKUP($C46,청소코드!$C$4:$J$188,3,FALSE) -> 센텀 2차 406 | E46: =VLOOKUP($C46,청소코드!$C$4:$J$188,4,FALSE) -> 1.5 | F46: 박연실 | I46: 완료 | J46: =SUM(K46:O46) -> 20000 | K46: =VLOOKUP($C46,청소코드!$C$4:$J$188,8,FALSE) -> 20000
A47: 46058 | B47: =TEXT(A47,"aaa") -> 목 | C47: F2 | D47: =VLOOKUP($C47,청소코드!$C$4:$J$188,3,FALSE) -> 오앤 401 | E47: =VLOOKUP($C47,청소코드!$C$4:$J$188,4,FALSE) -> 1 | F47: 박연실 | I47: 완료 | J47: =SUM(K47:O47) -> 18000 | K47: =VLOOKUP($C47,청소코드!$C$4:$J$188,8,FALSE) -> 18000
A48: 46058 | B48: =TEXT(A48,"aaa") -> 목 | C48: L2 | D48: =VLOOKUP($C48,청소코드!$C$4:$J$188,3,FALSE) -> 하람휴 902 | E48: =VLOOKUP($C48,청소코드!$C$4:$J$188,4,FALSE) -> 2 | F48: 이기섭 | I48: 완료 | J48: =SUM(K48:O48) -> 23000 | K48: =VLOOKUP($C48,청소코드!$C$4:$J$188,8,FALSE) -> 23000
A49: 46058 | B49: =TEXT(A49,"aaa") -> 목 | C49: C | D49: =VLOOKUP($C49,청소코드!$C$4:$J$188,3,FALSE) -> 청광1차 207 | E49: =VLOOKUP($C49,청소코드!$C$4:$J$188,4,FALSE) -> 0 | F49: 박연실 | I49: 완료 | J49: =SUM(K49:O49) -> 10000 | K49: =VLOOKUP($C49,청소코드!$C$4:$J$188,8,FALSE) -> 10000
A50: 46059 | B50: =TEXT(A50,"aaa") -> 금 | C50: U83 | D50: =VLOOKUP($C50,청소코드!$C$4:$J$188,3,FALSE) -> 성우 803 | E50: =VLOOKUP($C50,청소코드!$C$4:$J$188,4,FALSE) -> 3 | F50: 공숙길 | I50: 완료 | J50: =SUM(K50:O50) -> 30000 | K50: =VLOOKUP($C50,청소코드!$C$4:$J$188,8,FALSE) -> 30000
A51: 46059 | B51: =TEXT(A51,"aaa") -> 금 | C51: B24 | D51: =VLOOKUP($C51,청소코드!$C$4:$J$188,3,FALSE) -> 더하임 204 | E51: =VLOOKUP($C51,청소코드!$C$4:$J$188,4,FALSE) -> 1 | F51: 박연실 | I51: 완료 | J51: =SUM(K51:O51) -> 18000 | K51: =VLOOKUP($C51,청소코드!$C$4:$J$188,8,FALSE) -> 18000
A52: 46059 | B52: =TEXT(A52,"aaa") -> 금 | C52: B36 | D52: =VLOOKUP($C52,청소코드!$C$4:$J$188,3,FALSE) -> 더하임 306 | E52: =VLOOKUP($C52,청소코드!$C$4:$J$188,4,FALSE) -> 1.5 | F52: 박연실 | I52: 완료 | J52: =SUM(K52:O52) -> 20000 | K52: =VLOOKUP($C52,청소코드!$C$4:$J$188,8,FALSE) -> 20000
A53: 46059 | B53: =TEXT(A53,"aaa") -> 금 | C53: D3 | D53: =VLOOKUP($C53,청소코드!$C$4:$J$188,3,FALSE) -> 청광3차 507 | E53: =VLOOKUP($C53,청소코드!$C$4:$J$188,4,FALSE) -> 1 | F53: 김정은 | I53: 완료 | J53: =SUM(K53:O53) -> 18000 | K53: =VLOOKUP($C53,청소코드!$C$4:$J$188,8,FALSE) -> 18000
A54: 46059 | B54: =TEXT(A54,"aaa") -> 금 | C54: D6 | D54: =VLOOKUP($C54,청소코드!$C$4:$J$188,3,FALSE) -> 청광3차 1412 | E54: =VLOOKUP($C54,청소코드!$C$4:$J$188,4,FALSE) -> 1 | F54: 김정은 | I54: 완료 | J54: =SUM(K54:O54) -> 18000 | K54: =VLOOKUP($C54,청소코드!$C$4:$J$188,8,FALSE) -> 18000
...

Sheet 에어컨청소
B2: 1 | C2: 3
B3: 코드 | C3: 명칭 | D3: 청소일자 | E3: 개수 | F3: 워크맨 | G3: 리모콘 | H3: 급여 | I3: 성우비번
B4: A22 | C4: 예건 202 | D4: 46128 | E4: 1 | F4: 김정한 | G4: O | H4: =5000*E4 -> 5000
B5: A24 | C5: 예건 204 | D5: 46157 | E5: 1 | F5: 박연실 | G5: O | H5: =5000*E5 -> 5000
B6: A25 | C6: 예건 205 | D6: 46128 | E6: 1 | F6: 김정한 | G6: O | H6: =5000*E6 -> 5000
B7: A33 | C7: 예건 303 | D7: 46124 | E7: 1 | F7: 마디나 | G7: O | H7: =5000*E7 -> 5000
B8: A44 | C8: 예건 404 | H8: =5000*E8 -> 0
B9: A62 | C9: 예건 602 | D9: 46121 | E9: 1 | F9: 김정은 | G9: O | H9: =5000*E9 -> 5000
B10: A72 | C10: 예건 702 | H10: =5000*E10 -> 0
B11: A82 | C11: 예건 802 | H11: =5000*E11 -> 0
B12: A92 | C12: 예건 902 | D12: 46126 | E12: 1 | F12: 김정한 | G12: O | H12: =5000*E12 -> 5000
B13: B101 | C13: 더하임 1001 | H13: =5000*E13 -> 0
B14: B102 | C14: 더하임 1002 | D14: 46131 | E14: 1 | F14: 김정한 | G14: O | H14: =5000*E14 -> 5000
B15: B103 | C15: 더하임 1003 | D15: 46131 | E15: 1 | F15: 김정한 | G15: O | H15: =5000*E15 -> 5000
B16: B104 | C16: 더하임 1004 | D16: 46131 | E16: 1 | F16: 김정한 | G16: O | H16: =5000*E16 -> 5000
B17: B105 | C17: 더하임 1005 | D17: 46121 | E17: 1 | F17: 박연실 | G17: X | H17: =5000*E17 -> 5000
B18: B106 | C18: 더하임 1006 | D18: 46119 | E18: 1 | F18: 박연실 | G18: O | H18: =5000*E18 -> 5000
B19: B22 | C19: 더하임 202 | D19: 46121 | E19: 1 | F19: 박연실 | G19: O | H19: =5000*E19 -> 5000
B20: B23 | C20: 더하임 203 | D20: 46130 | E20: 1 | F20: 박연실 | G20: X | H20: =5000*E20 -> 5000
B21: B24 | C21: 더하임 204 | D21: 46131 | E21: 1 | F21: 김정한 | G21: O | H21: =5000*E21 -> 5000
B22: B25 | C22: 더하임 205 | D22: 46122 | E22: 1 | F22: 마디나 | G22: O | H22: =5000*E22 -> 5000
B23: B34 | C23: 더하임 304 | D23: 46131 | E23: 1 | F23: 박연실 | G23: O | H23: =5000*E23 -> 5000
B24: B35 | C24: 더하임 305 | D24: 46132 | E24: 1 | F24: 박연실 | G24: o(건전지없음) | H24: =5000*E24 -> 5000
B25: B56 | C25: 더하임 506 | D25: 46119 | E25: 1 | F25: 박연실 | G25: O | H25: =5000*E25 -> 5000
B26: B64 | C26: 더하임 604 | H26: =5000*E26 -> 0
B27: B91 | C27: 더하임 901 | D27: 46120 | E27: 1 | F27: 박연실 | G27: O | H27: =5000*E27 -> 5000
B28: B93 | C28: 더하임 903 | H28: =5000*E28 -> 0
B29: B94 | C29: 더하임 904 | H29: =5000*E29 -> 0
B30: B95 | C30: 더하임 905 | H30: =5000*E30 -> 0
B31: C | C31: 청광1차 207 | H31: =5000*E31 -> 0
B32: C5 | C32: 청광1차 910 | H32: =5000*E32 -> 0
B33: C6 | C33: 청광1차 1303 | D33: 46131 | E33: 1 | F33: 유민정 | G33: O | H33: =5000*E33 -> 5000
B34: C7 | C34: 길동다성 506 | D34: 46139 | E34: 1 | F34: 마디나 | G34: X | H34: =5000*E34 -> 5000
B35: D1 | C35: 청광3차 1416 | D35: 46131 | E35: 1 | F35: 유민정 | G35: O | H35: =5000*E35 -> 5000
B36: D3 | C36: 청광3차 507 | H36: =5000*E36 -> 0
B37: D4 | C37: 청광3차 806 | D37: 46119 | E37: 1 | F37: 유민정 | G37: O | H37: =5000*E37 -> 5000
B38: D6 | C38: 청광3차 1412 | D38: 46119 | E38: 1 | F38: 유민정 | G38: O | H38: =5000*E38 -> 5000
B39: D8 | C39: 강동QV 1604 | D39: 46119 | E39: 1 | F39: 김정은 | G39: O | H39: =5000*E39 -> 5000
B40: E1 | C40: 르센티 1801 | H40: =5000*E40 -> 0
B41: E3 | C41: 렘브 204 | D41: 46120 | E41: 1 | F41: 박연실 | G41: O | H41: =5000*E41 -> 5000
...

Sheet 이번주
A1: 청소일자 | B1: 요일 | C1: 코드 | D1: 숙소명 | E1: 방 | F1: 워크맨 | G1: 체크사항/요구사항 | H1: 입금체크 | I1: 입력체크 | J1: 운영 지출
A2: 청소일자 | B2: 요일 | C2: 코드 | D2: 숙소명 | E2: 수 | F2: 담당 | G2: 체크사항/요구사항 | H2: 입금체크 | I2: 입력체크 | J2: 총 금액(B) | K2: 기본비 | L2: 추가비 | M2: 침구 관리 | N2: 세탁비 | O2: 백업
A3: 46147 | B3: =TEXT(A3,"aaa") -> 화 | C3: A25 | D3: =VLOOKUP($C3,청소코드!$C$4:$J$188,3,FALSE) -> 예건 205 | E3: =VLOOKUP($C3,청소코드!$C$4:$J$188,4,FALSE) -> 1 | F3: 김정은 | I3: 완료 | J3: =SUM(K3:O3) -> 18000 | K3: =VLOOKUP($C3,청소코드!$C$4:$J$188,8,FALSE) -> 18000
A4: 46147 | B4: =TEXT(A4,"aaa") -> 화 | C4: A82 | D4: =VLOOKUP($C4,청소코드!$C$4:$J$188,3,FALSE) -> 예건 802 | E4: =VLOOKUP($C4,청소코드!$C$4:$J$188,4,FALSE) -> 1 | F4: 김정은 | I4: 완료 | J4: =SUM(K4:O4) -> 18000 | K4: =VLOOKUP($C4,청소코드!$C$4:$J$188,8,FALSE) -> 18000
A5: 46147 | B5: =TEXT(A5,"aaa") -> 화 | C5: U24 | D5: =VLOOKUP($C5,청소코드!$C$4:$J$188,3,FALSE) -> 성우 204 | E5: =VLOOKUP($C5,청소코드!$C$4:$J$188,4,FALSE) -> 2 | F5: 김정은 | I5: 완료 | J5: =SUM(K5:O5) -> 23000 | K5: =VLOOKUP($C5,청소코드!$C$4:$J$188,8,FALSE) -> 23000
A6: 46147 | B6: =TEXT(A6,"aaa") -> 화 | C6: U93 | D6: =VLOOKUP($C6,청소코드!$C$4:$J$188,3,FALSE) -> 성우 903 | E6: =VLOOKUP($C6,청소코드!$C$4:$J$188,4,FALSE) -> 3 | F6: 김정은 | I6: 완료 | J6: =SUM(K6:O6) -> 30000 | K6: =VLOOKUP($C6,청소코드!$C$4:$J$188,8,FALSE) -> 30000
A7: 46147 | B7: =TEXT(A7,"aaa") -> 화 | C7: B103 | D7: =VLOOKUP($C7,청소코드!$C$4:$J$188,3,FALSE) -> 더하임 1003 | E7: =VLOOKUP($C7,청소코드!$C$4:$J$188,4,FALSE) -> 1 | F7: 주경태 | I7: 완료 | J7: =SUM(K7:O7) -> 18000 | K7: =VLOOKUP($C7,청소코드!$C$4:$J$188,8,FALSE) -> 18000
A8: 46147 | B8: =TEXT(A8,"aaa") -> 화 | C8: B104 | D8: =VLOOKUP($C8,청소코드!$C$4:$J$188,3,FALSE) -> 더하임 1004 | E8: =VLOOKUP($C8,청소코드!$C$4:$J$188,4,FALSE) -> 1 | F8: 주경태 | I8: 완료 | J8: =SUM(K8:O8) -> 18000 | K8: =VLOOKUP($C8,청소코드!$C$4:$J$188,8,FALSE) -> 18000
A9: 46147 | B9: =TEXT(A9,"aaa") -> 화 | C9: B23 | D9: =VLOOKUP($C9,청소코드!$C$4:$J$188,3,FALSE) -> 더하임 203 | E9: =VLOOKUP($C9,청소코드!$C$4:$J$188,4,FALSE) -> 1 | F9: 주경태 | I9: 완료 | J9: =SUM(K9:O9) -> 18000 | K9: =VLOOKUP($C9,청소코드!$C$4:$J$188,8,FALSE) -> 18000
A10: 46147 | B10: =TEXT(A10,"aaa") -> 화 | C10: B24 | D10: =VLOOKUP($C10,청소코드!$C$4:$J$188,3,FALSE) -> 더하임 204 | E10: =VLOOKUP($C10,청소코드!$C$4:$J$188,4,FALSE) -> 1 | F10: 박연실 | I10: 완료 | J10: =SUM(K10:O10) -> 18000 | K10: =VLOOKUP($C10,청소코드!$C$4:$J$188,8,FALSE) -> 18000
A11: 46147 | B11: =TEXT(A11,"aaa") -> 화 | C11: B91 | D11: =VLOOKUP($C11,청소코드!$C$4:$J$188,3,FALSE) -> 더하임 901 | E11: =VLOOKUP($C11,청소코드!$C$4:$J$188,4,FALSE) -> 1 | F11: 박연실 | I11: 완료 | J11: =SUM(K11:O11) -> 18000 | K11: =VLOOKUP($C11,청소코드!$C$4:$J$188,8,FALSE) -> 18000
A12: 46147 | B12: =TEXT(A12,"aaa") -> 화 | C12: B94 | D12: =VLOOKUP($C12,청소코드!$C$4:$J$188,3,FALSE) -> 더하임 904 | E12: =VLOOKUP($C12,청소코드!$C$4:$J$188,4,FALSE) -> 1 | F12: 박연실 | I12: 완료 | J12: =SUM(K12:O12) -> 18000 | K12: =VLOOKUP($C12,청소코드!$C$4:$J$188,8,FALSE) -> 18000
A13: 46147 | B13: =TEXT(A13,"aaa") -> 화 | C13: B95 | D13: =VLOOKUP($C13,청소코드!$C$4:$J$188,3,FALSE) -> 더하임 905 | E13: =VLOOKUP($C13,청소코드!$C$4:$J$188,4,FALSE) -> 1 | F13: 박연실 | I13: 완료 | J13: =SUM(K13:O13) -> 18000 | K13: =VLOOKUP($C13,청소코드!$C$4:$J$188,8,FALSE) -> 18000
A14: 46147 | B14: =TEXT(A14,"aaa") -> 화 | C14: S1 | D14: =VLOOKUP($C14,청소코드!$C$4:$J$188,3,FALSE) -> 미사아름채 1310호 | E14: =VLOOKUP($C14,청소코드!$C$4:$J$188,4,FALSE) -> 1.5 | F14: 박연실 | I14: 완료 | J14: =SUM(K14:O14) -> 20000 | K14: =VLOOKUP($C14,청소코드!$C$4:$J$188,8,FALSE) -> 20000
... A26: 46148 | B26: =TEXT(A26,"aaa") -> 수 | C26: T46 | D26: =VLOOKUP($C26,청소코드!$C$4:$J$188,3,FALSE) -> 센텀 2차 406 | E26: =VLOOKUP($C26,청소코드!$C$4:$J$188,4,FALSE) -> 1.5 | F26: 박연실 | I26: 완료 | J26: =SUM(K26:O26) -> 20000 | K26: =VLOOKUP($C26,청소코드!$C$4:$J$188,8,FALSE) -> 20000
A27: 46148 | B27: =TEXT(A27,"aaa") -> 수 | C27: K1 | D27: =VLOOKUP($C27,청소코드!$C$4:$J$188,3,FALSE) -> 선일 101 | E27: =VLOOKUP($C27,청소코드!$C$4:$J$188,4,FALSE) -> 2 | F27: 박연실 | G27: 긴급 | I27: 완료 | J27: =SUM(K27:O27) -> 40000 | K27: =VLOOKUP($C27,청소코드!$C$4:$J$188,8,FALSE) -> 23000 | L27: 17000
A28: 46148 | B28: =TEXT(A28,"aaa") -> 수 | C28: D1 | D28: =VLOOKUP($C28,청소코드!$C$4:$J$188,3,FALSE) -> 청광3차 1416 | E28: =VLOOKUP($C28,청소코드!$C$4:$J$188,4,FALSE) -> 1 | F28: 김정은 | I28: 완료 | J28: =SUM(K28:O28) -> 18000 | K28: =VLOOKUP($C28,청소코드!$C$4:$J$188,8,FALSE) -> 18000
A29: 46148 | B29: =TEXT(A29,"aaa") -> 수 | C29: E3 | D29: =VLOOKUP($C29,청소코드!$C$4:$J$188,3,FALSE) -> 렘브 204 | E29: =VLOOKUP($C29,청소코드!$C$4:$J$188,4,FALSE) -> 1 | F29: 김정은 | I29: 완료 | J29: =SUM(K29:O29) -> 18000 | K29: =VLOOKUP($C29,청소코드!$C$4:$J$188,8,FALSE) -> 18000
A30: 46148 | B30: =TEXT(A30,"aaa") -> 수 | C30: A25 | D30: =VLOOKUP($C30,청소코드!$C$4:$J$188,3,FALSE) -> 예건 205 | E30: =VLOOKUP($C30,청소코드!$C$4:$J$188,4,FALSE) -> 1 | F30: 주경태 | I30: 완료 | J30: =SUM(K30:O30) -> 18000 | K30: =VLOOKUP($C30,청소코드!$C$4:$J$188,8,FALSE) -> 18000
A31: 46148 | B31: =TEXT(A31,"aaa") -> 수 | C31: J2 | D31: =VLOOKUP($C31,청소코드!$C$4:$J$188,3,FALSE) -> 은성 603 | E31: =VLOOKUP($C31,청소코드!$C$4:$J$188,4,FALSE) -> 1 | F31: 주경태 | I31: 완료 | J31: =SUM(K31:O31) -> 18000 | K31: =VLOOKUP($C31,청소코드!$C$4:$J$188,8,FALSE) -> 18000
A32: 46148 | B32: =TEXT(A32,"aaa") -> 수 | C32: B104 | D32: =VLOOKUP($C32,청소코드!$C$4:$J$188,3,FALSE) -> 더하임 1004 | E32: =VLOOKUP($C32,청소코드!$C$4:$J$188,4,FALSE) -> 1 | F32: 손혜영 | I32: 완료 | J32: =SUM(K32:O32) -> 18000 | K32: =VLOOKUP($C32,청소코드!$C$4:$J$188,8,FALSE) -> 18000
A33: 46148 | B33: =TEXT(A33,"aaa") -> 수 | C33: B105 | D33: =VLOOKUP($C33,청소코드!$C$4:$J$188,3,FALSE) -> 더하임 1005 | E33: =VLOOKUP($C33,청소코드!$C$4:$J$188,4,FALSE) -> 1 | F33: 손혜영 | I33: 완료 | J33: =SUM(K33:O33) -> 18000 | K33: =VLOOKUP($C33,청소코드!$C$4:$J$188,8,FALSE) -> 18000
A34: 46148 | B34: =TEXT(A34,"aaa") -> 수 | C34: S1 | D34: =VLOOKUP($C34,청소코드!$C$4:$J$188,3,FALSE) -> 미사아름채 1310호 | E34: =VLOOKUP($C34,청소코드!$C$4:$J$188,4,FALSE) -> 1.5 | F34: 손혜영 | I34: 완료 | J34: =SUM(K34:O34) -> 20000 | K34: =VLOOKUP($C34,청소코드!$C$4:$J$188,8,FALSE) -> 20000
A35: 46148 | B35: =TEXT(A35,"aaa") -> 수 | C35: B24 | D35: =VLOOKUP($C35,청소코드!$C$4:$J$188,3,FALSE) -> 더하임 204 | E35: =VLOOKUP($C35,청소코드!$C$4:$J$188,4,FALSE) -> 1 | F35: 공숙길 | I35: 완료 | J35: =SUM(K35:O35) -> 18000 | K35: =VLOOKUP($C35,청소코드!$C$4:$J$188,8,FALSE) -> 18000
A36: 46148 | B36: =TEXT(A36,"aaa") -> 수 | C36: B91 | D36: =VLOOKUP($C36,청소코드!$C$4:$J$188,3,FALSE) -> 더하임 901 | E36: =VLOOKUP($C36,청소코드!$C$4:$J$188,4,FALSE) -> 1 | F36: 공숙길 | I36: 완료 | J36: =SUM(K36:O36) -> 18000 | K36: =VLOOKUP($C36,청소코드!$C$4:$J$188,8,FALSE) -> 18000
A37: 46148 | B37: =TEXT(A37,"aaa") -> 수 | C37: B95 | D37: =VLOOKUP($C37,청소코드!$C$4:$J$188,3,FALSE) -> 더하임 905 | E37: =VLOOKUP($C37,청소코드!$C$4:$J$188,4,FALSE) -> 1 | F37: 공숙길 | I37: 완료 | J37: =SUM(K37:O37) -> 18000 | K37: =VLOOKUP($C37,청소코드!$C$4:$J$188,8,FALSE) -> 18000
A38: 46148 | B38: =TEXT(A38,"aaa") -> 수 | C38: L3 | D38: =VLOOKUP($C38,청소코드!$C$4:$J$188,3,FALSE) -> 하람휴 1102 | E38: =VLOOKUP($C38,청소코드!$C$4:$J$188,4,FALSE) -> 2 | F38: 이기섭 | I38: 완료 | J38: =SUM(K38:O38) -> 23000 | K38: =VLOOKUP($C38,청소코드!$C$4:$J$188,8,FALSE) -> 23000
A39: 46148 | B39: =TEXT(A39,"aaa") -> 수 | C39: V12 | D39: =VLOOKUP($C39,청소코드!$C$4:$J$188,3,FALSE) -> 대치동 102호 | E39: =VLOOKUP($C39,청소코드!$C$4:$J$188,4,FALSE) -> 1 | F39: 김남주 | I39: 완료 | J39: =SUM(K39:O39) -> 18000 | K39: =VLOOKUP($C39,청소코드!$C$4:$J$188,8,FALSE) -> 18000
A40: 46148 | B40: =TEXT(A40,"aaa") -> 수 | C40: C | D40: =VLOOKUP($C40,청소코드!$C$4:$J$188,3,FALSE) -> 청광1차 207 | E40: =VLOOKUP($C40,청소코드!$C$4:$J$188,4,FALSE) -> 0 | F40: 박연실 | I40: 완료 | J40: =SUM(K40:O40) -> 10000 | K40: =VLOOKUP($C40,청소코드!$C$4:$J$188,8,FALSE) -> 10000
A41: 46149 | B41: =TEXT(A41,"aaa") -> 목 | D41: =VLOOKUP($C41,청소코드!$C$4:$J$188,3,FALSE) -> #N/A | E41: =VLOOKUP($C41,청소코드!$C$4:$J$188,4,FALSE) -> #N/A | J41: =SUM(K41:O41) -> #N/A | K41: =VLOOKUP($C41,청소코드!$C$4:$J$188,8,FALSE) -> #N/A
A42: 46149 | B42: =TEXT(A42,"aaa") -> 목 | D42: =VLOOKUP($C42,청소코드!$C$4:$J$188,3,FALSE) -> #N/A | E42: =VLOOKUP($C42,청소코드!$C$4:$J$188,4,FALSE) -> #N/A | J42: =SUM(K42:O42) -> #N/A | K42: =VLOOKUP($C42,청소코드!$C$4:$J$188,8,FALSE) -> #N/A
B43: =TEXT(A43,"aaa") -> 토 | D43: =VLOOKUP($C43,청소코드!$C$4:$J$188,3,FALSE) -> #N/A | E43: =VLOOKUP($C43,청소코드!$C$4:$J$188,4,FALSE) -> #N/A | J43: =SUM(K43:O43) -> #N/A | K43: =VLOOKUP($C43,청소코드!$C$4:$J$188,8,FALSE) -> #N/A
B44: =TEXT(A44,"aaa") -> 토 | D44: =VLOOKUP($C44,청소코드!$C$4:$J$188,3,FALSE) -> #N/A | E44: =VLOOKUP($C44,청소코드!$C$4:$J$188,4,FALSE) -> #N/A | J44: =SUM(K44:O44) -> #N/A | K44: =VLOOKUP($C44,청소코드!$C$4:$J$188,8,FALSE) -> #N/A
B45: =TEXT(A45,"aaa") -> 토 | D45: =VLOOKUP($C45,청소코드!$C$4:$J$188,3,FALSE) -> #N/A | E45: =VLOOKUP($C45,청소코드!$C$4:$J$188,4,FALSE) -> #N/A | J45: =SUM(K45:O45) -> #N/A | K45: =VLOOKUP($C45,청소코드!$C$4:$J$188,8,FALSE) -> #N/A
B46: =TEXT(A46,"aaa") -> 토 | D46: =VLOOKUP($C46,청소코드!$C$4:$J$188,3,FALSE) -> #N/A | E46: =VLOOKUP($C46,청소코드!$C$4:$J$188,4,FALSE) -> #N/A | J46: =SUM(K46:O46) -> #N/A | K46: =VLOOKUP($C46,청소코드!$C$4:$J$188,8,FALSE) -> #N/A
B47: =TEXT(A47,"aaa") -> 토 | D47: =VLOOKUP($C47,청소코드!$C$4:$J$188,3,FALSE) -> #N/A | E47: =VLOOKUP($C47,청소코드!$C$4:$J$188,4,FALSE) -> #N/A | J47: =SUM(K47:O47) -> #N/A | K47: =VLOOKUP($C47,청소코드!$C$4:$J$188,8,FALSE) -> #N/A
B48: =TEXT(A48,"aaa") -> 토 | D48: =VLOOKUP($C48,청소코드!$C$4:$J$188,3,FALSE) -> #N/A | E48: =VLOOKUP($C48,청소코드!$C$4:$J$188,4,FALSE) -> #N/A | J48: =SUM(K48:O48) -> #N/A | K48: =VLOOKUP($C48,청소코드!$C$4:$J$188,8,FALSE) -> #N/A
B49: =TEXT(A49,"aaa") -> 토 | D49: =VLOOKUP($C49,청소코드!$C$4:$J$188,3,FALSE) -> #N/A | E49: =VLOOKUP($C49,청소코드!$C$4:$J$188,4,FALSE) -> #N/A | J49: =SUM(K49:O49) -> #N/A | K49: =VLOOKUP($C49,청소코드!$C$4:$J$188,8,FALSE) -> #N/A
B50: =TEXT(A50,"aaa") -> 토 | D50: =VLOOKUP($C50,청소코드!$C$4:$J$188,3,FALSE) -> #N/A | E50: =VLOOKUP($C50,청소코드!$C$4:$J$188,4,FALSE) -> #N/A | J50: =SUM(K50:O50) -> #N/A | K50: =VLOOKUP($C50,청소코드!$C$4:$J$188,8,FALSE) -> #N/A
B51: =TEXT(A51,"aaa") -> 토 | D51: =VLOOKUP($C51,청소코드!$C$4:$J$188,3,FALSE) -> #N/A | E51: =VLOOKUP($C51,청소코드!$C$4:$J$188,4,FALSE) -> #N/A | J51: =SUM(K51:O51) -> #N/A | K51: =VLOOKUP($C51,청소코드!$C$4:$J$188,8,FALSE) -> #N/A
...

Sheet 최종입금
A2: 2월 | B2: 1주 | D2: 2월 | E2: 2주 | G2: 2월 | H2: 3주 | J2: 2월 | K2: 4주
A3: 행 레이블 | B3: 합계 : 총 금액(B) | D3: 행 레이블 | E3: 합계 : 총 금액(B) | G3: 행 레이블 | H3: 합계 : 총 금액(B) | J3: 행 레이블 | K3: 합계 : 총 금액(B)
A4: 공숙길 | B4: 201000 | C4: 완료 | D4: 공숙길 | E4: 260000 | F4: 완료 | G4: 공숙길 | H4: 376000 | I4: 완료 | J4: 강수미 | K4: 100000 | L4: 완료
A5: 김민주 | B5: 25000 | C5: 완료 | D5: 김정은 | E5: 406000 | F5: 완료 | G5: 김민주 | H5: 25000 | I5: 완료 | J5: 공숙길 | K5: 220000 | L5: 완료
A6: 김정은 | B6: 325000 | C6: 완료 | D6: 김정한 | E6: 149000 | F6: 완료 | G6: 김정은 | H6: 345000 | I6: 완료 | J6: 김남주 | K6: 90800 | L6: 완료
A7: 김정한 | B7: 134000 | C7: 완료 | D7: 류지영 | E7: 418000 | F7: 완료 | G7: 김정한 | H7: 150000 | I7: 완료 | J7: 김정은 | K7: 366000 | L7: 완료
A8: 류지영 | B8: 431000 | C8: 완료 | D8: 마디나 | E8: 286000 | F8: 완료 | G8: 류지영 | H8: 363000 | I8: 완료 | J8: 김정한 | K8: 132000 | L8: 완료
A9: 마디나 | B9: 308000 | C9: 완료 | D9: 박연실 | E9: 448000 | F9: 완료 | G9: 마디나 | H9: 299000 | I9: 완료 | J9: 류지영 | K9: 116000 | L9: 완료
A10: 박연실 | B10: 404000 | C10: 완료 | D10: 오재관 | E10: 131000 | F10: 완료 | G10: 박연실 | H10: 400000 | I10: 완료 | J10: 마디나 | K10: 252000 | L10: 완료
A11: 오재관 | B11: 98000 | C11: 완료 | D11: 유민정 | E11: 332500 | F11: 완료 | G11: 오재관 | H11: 137000 | I11: 완료 | J11: 박연실 | K11: 405000 | L11: 완료
A12: 유민정 | B12: 278500 | C12: 완료 | D12: 이기섭 | E12: 158000 | F12: 완료 | G12: 유민정 | H12: 128000 | I12: 완료 | J12: 유민정 | K12: 130000 | L12: 완료
A13: 이기섭 | B13: 184000 | C13: 완료 | D13: 장미숙 | E13: 31500 | F13: 완료 | G13: 이기섭 | H13: 115000 | I13: 완료 | J13: 이기섭 | K13: 125000 | L13: 완료
A14: 장미숙 | B14: 23000 | C14: 완료 | D14: 총합계 | E14: 2620000 | G14: 장미숙 | H14: 27000 | I14: 완료 | J14: 총합계 | K14: 1936800
A15: 총합계 | B15: 2411500 | G15: 황월규 | H15: 40000 | I15: 완료
G16: 총합계 | H16: 2405000
A19: 3월 | B19: 1주 | D19: 3월 | E19: 2주 | G19: 3월 | H19: 3주 | J19: 3월 | K19: 4주
A20: 행 레이블 | B20: 합계 : 총 금액(B) | D20: 행 레이블 | E20: 합계 : 총 금액(B) | G20: 행 레이블 | H20: 합계 : 총 금액(B) | J20: 행 레이블 | K20: 합계 : 총 금액(B)
A21: 공숙길 | B21: 157000 | C21: 완료 | D21: 공숙길 | E21: 195000 | G21: 강수미 | H21: 40000 | I21: 완료 | J21: 강수미 | K21: 82000 | L21: 완료
A22: 김남주 | B22: 101000 | C22: 완료 | D22: 김남주 | E22: 164000 | G22: 공숙길 | H22: 214000 | I22: 완료 | J22: 공숙길 | K22: 124000 | L22: 완료
A23: 김우현 | B23: 30000 | C23: 완료 | D23: 김우현 | E23: 34000 | G23: 김남주 | H23: 63000 | I23: 완료 | J23: 김남주 | K23: 80000 | L23: 완료
A24: 김정은 | B24: 257000 | C24: 완료 | D24: 김정은 | E24: 171000 | G24: 김정은 | H24: 144000 | I24: 완료 | J24: 김우현 | K24: 84000 | L24: 완료
A25: 김정한 | B25: 192000 | C25: 완료 | D25: 김정한 | E25: 92000 | G25: 김정한 | H25: 87000 | I25: 완료 | J25: 김정은 | K25: 234000 | L25: 완료
A26: 류지영 | B26: 184000 | C26: 완료 | D26: 류지영 | E26: 172000 | G26: 류지영 | H26: 299000 | I26: 완료 | J26: 김정한 | K26: 133000 | L26: 완료
A27: 마디나 | B27: 169000 | C27: 완료 | D27: 마디나 | E27: 112000 | G27: 마디나 | H27: 151000 | I27: 완료 | J27: 류지영 | K27: 184000 | L27: 완료
A28: 박연실 | B28: 341000 | C28: 완료 | D28: 박연실 | E28: 363000 | G28: 박연실 | H28: 263000 | I28: 완료 | J28: 마디나 | K28: 173000 | L28: 완료
A29: 유민정 | B29: 177000 | C29: 완료 | D29: 유민정 | E29: 174000 | G29: 유민정 | H29: 172000 | I29: 완료 | J29: 박연실 | K29: 309000 | L29: 완료
A30: 이기섭 | B30: 51000 | C30: 완료 | D30: 이기섭 | E30: 125000 | G30: 이기섭 | H30: 97000 | I30: 완료 | J30: 유민정 | K30: 260000 | L30: 완료
A31: 총합계 | B31: 1659000 | D31: 장미숙 | E31: 55500 | G31: 총합계 | H31: 1530000 | J31: 이기섭 | K31: 69000 | L31: 완료
A32: +강수미 5천원 | B32: (기상악화) | C32: 완료 | D32: 총합계 | E32: 1657500 | J32: 총합계 | K32: 1732000
A39: 4월 | B39: 1주 | D39: 4월 | E39: 2주 | G39: 4월 | H39: 3주 | J39: 4월 | K39: 4주
A40: 행 레이블 | B40: 합계 : 총 금액(B) | D40: 행 레이블 | E40: 합계 : 총 금액(B) | G40: 행 레이블 | H40: 합계 : 총 금액(B) | J40: 행 레이블 | K40: 합계 : 총 금액(B)
A41: 공숙길 | B41: 185000 | C41: 완료 | D41: 공숙길 | E41: 293000 | F41: 완료 | G41: 강수미 | H41: 40000 | I41: 완료 | J41: 공숙길 | K41: 92000 | L41: 완료
A42: 김남주 | B42: 60000 | C42: 완료 | D42: 김남주 | E42: 161000 | F42: 완료 | G42: 공숙길 | H42: 181000 | I42: 완료 | J42: 김남주 | K42: 150000 | L42: 완료
A43: 김우현 | B43: 137500 | C43: 완료 | D43: 김정은 | E43: 298000 | F43: 완료 | G43: 김남주 | H43: 200000 | I43: 완료 | J43: 김정은 | K43: 265000 | L43: 완료
A44: 김정은 | B44: 139000 | C44: 완료 | D44: 류지영 | E44: 18000 | F44: 완료 | G44: 김정은 | H44: 274000 | I44: 완료 | J44: 김정한 | K44: 196000 | L44: 완료
A45: 김정한 | B45: 138000 | C45: 완료 | D45: 마디나 | E45: 172000 | F45: 완료 | G45: 김정한 | H45: 225000 | I45: 완료 | J45: 류지영 | K45: 144000 | L45: 완료
A46: 류지영 | B46: 43000 | C46: 완료 | D46: 박연실 | E46: 268000 | F46: 완료 | G46: 류지영 | H46: 58000 | I46: 완료 | J46: 마디나 | K46: 310000 | L46: 완료
A47: 마디나 | B47: 259000 | C47: 완료 | D47: 유민정 | E47: 195000 | F47: 완료 | G47: 마디나 | H47: 339000 | I47: 완료 | J47: 박금주 | K47: 36000 | L47: 완료
A48: 박연실 | B48: 347000 | C48: 완료 | D48: 이기섭 | E48: 120000 | F48: 완료 | G48: 박연실 | H48: 375000 | I48: 완료 | J48: 박연실 | K48: 421000 | L48: 완료
A49: 유민정 | B49: 241000 | C49: 완료 | D49: 총합계 | E49: 1525000 | G49: 유민정 | H49: 236000 | I49: 완료 | J49: 손혜영 | K49: 56000 | L49: 완료
...

Sheet 계좌 및 개인정보
A1: 인원 | B1: 연락처 | C1: 은행 | D1: 계좌 | E1: 예금주명
A2: 마디나 | B2: 010-8447-3332 | C2: 토스 | D2: 1001-8877-7919 | E2: 가
A3: 김정은 | B3: 010-4737-7534 | C3: 신한 | D3: 110-611-123497 | E3: 나
A4: 유민정 | B4: 010-5906-7472 | C4: 우체국 | D4: 013003-02-307591 | E4: 다
A5: 류지영 | B5: 010-4509-5717 | C5: 카카오 | D5: 3333-1742-08879 | E5: 라
A6: 김정한 | B6: 010-7626-1955 | C6: 신한 | D6: 110-314-724-430 | E6: 마
A7: 박연실 | B7: 010-8752-8202 | C7: 기업 | D7: 060-018435-02-014 | E7: 바
A8: 공숙길 | B8: 010-5520-3206 | C8: 우체국 | D8: 013102-02-582835 | E8: 사
A9: 장승연 | B9: 010-2773-2244 | C9: 하나 | D9: 142-910597-91407 | E9: 아
A10: 강수미 | B10: 010-2272-4424 | C10: 신한 | D10: 110-191-641767 | E10: 자
A11: 박진성 | B11: 010-6288-7469 | C11: 농협 | D11: 100029-56-096965 | E11: 차
A12: 김민주 | B12: 010-3265-0145 | C12: 기업 | D12: 540-004738-02-011 | E12: 카
... A18: 한해숙 | B18: 010-5130-4017 | C18: 농협 | D18: 815-0875-6067-124 | E18: C
A19: 황월규 | B19: 010-8442-7877 | C19: 신한 | D19: 351-12-208982
A20: 김남주 | B20: 010-9066-3663 | C20: 국민 | D20: 088210486481
A21: 권은정 | B21: 010-4443-0095 | C21: 농협 | D21: 302-7926-6258-41
A22: 손혜영 | B22: 010-6252-7845 | C22: 카카오 | D22: 3333332544587
A23: 박금주 | C23: 카카오 | D23: 3333177575080
A24: 주경태 | B24: 010-4299-8076 | C24: 신협 | D24: 142001941581
